Traceback (most recent call last):
  File "/usr/local/lib64/python3.8/site-packages/aiohttp/connector.py", line 969, in _wrap_create_connection
    return await self._loop.create_connection(*args, **kwargs)  # type: ignore  # noqa
  File "/usr/lib64/python3.8/asyncio/base_events.py", line 1025, in create_connection
    raise exceptions[0]
  File "/usr/lib64/python3.8/asyncio/base_events.py", line 1010, in create_connection
    sock = await self._connect_sock(
  File "/usr/lib64/python3.8/asyncio/base_events.py", line 924, in _connect_sock
    await self.sock_connect(sock, address)
  File "/usr/lib64/python3.8/asyncio/selector_events.py", line 494, in sock_connect
    return await fut
  File "/usr/lib64/python3.8/asyncio/selector_events.py", line 499, in _sock_connect
    sock.connect(address)
OSError: [Errno 101] Network is unreachable

The above exception was the direct cause of the following exception:

Traceback (most recent call last):
  File "/usr/local/lib/python3.8/site-packages/graia/broadcast/__init__.py", line 204, in Executor
    result = await run_always_await_safely(
  File "/usr/local/lib/python3.8/site-packages/graia/broadcast/utilles.py", line 30, in run_always_await_safely
    return await callable(*args, **kwargs)
  File "/home/aqiang/project/mcl-1.0.4/sagiri-bot/modules/Pixiv_api.py", line 27, in abbreviated_prediction_handler
    await GroupMessageSender(result.strategy).send(app, result.message, message, group, member)
  File "/home/aqiang/project/mcl-1.0.4/sagiri-bot/SAGIRIBOT/MessageSender/MessageSender.py", line 52, in send
    await self.__strategy.send(app, message, origin_message, group, member)
  File "/home/aqiang/project/mcl-1.0.4/sagiri-bot/SAGIRIBOT/MessageSender/Strategy.py", line 80, in send
    await (await self.__strategy_type.send_method(app))(target_field, message)
  File "/usr/local/lib/python3.8/site-packages/graia/application/__init__.py", line 67, in wrapped_network_action_callable
    return await network_action_callable(self, *args, **kwargs)
  File "/usr/local/lib/python3.8/site-packages/graia/application/utilles.py", line 27, in wrapper
    return await func(self, *args, **kwargs)
  File "/usr/local/lib/python3.8/site-packages/graia/application/__init__.py", line 630, in sendGroupMessage
    message_result = await message.build()
  File "/usr/local/lib/python3.8/site-packages/graia/application/message/chain.py", line 223, in build
    await run_always_await(
  File "/usr/local/lib/python3.8/site-packages/graia/broadcast/utilles.py", line 23, in run_always_await
    return await any_callable
  File "/usr/local/lib/python3.8/site-packages/graia/application/message/elements/internal.py", line 294, in toExternal
    async with app.session.get(self.url) as response:
  File "/usr/local/lib64/python3.8/site-packages/aiohttp/client.py", line 1117, in __aenter__
    self._resp = await self._coro
  File "/usr/local/lib64/python3.8/site-packages/aiohttp/client.py", line 520, in _request
    conn = await self._connector.connect(
  File "/usr/local/lib64/python3.8/site-packages/aiohttp/connector.py", line 535, in connect
    proto = await self._create_connection(req, traces, timeout)
  File "/usr/local/lib64/python3.8/site-packages/aiohttp/connector.py", line 892, in _create_connection
    _, proto = await self._create_direct_connection(req, traces, timeout)
  File "/usr/local/lib64/python3.8/site-packages/aiohttp/connector.py", line 1051, in _create_direct_connection
    raise last_exc
  File "/usr/local/lib64/python3.8/site-packages/aiohttp/connector.py", line 1020, in _create_direct_connection
    transp, proto = await self._wrap_create_connection(
  File "/usr/local/lib64/python3.8/site-packages/aiohttp/connector.py", line 975, in _wrap_create_connection
    raise client_error(req.connection_key, exc) from exc
aiohttp.client_exceptions.ClientConnectorError: Cannot connect to host i.pixiv.cat:443 ssl:default [Network is unreachable]